[2023-11-24T14:55:46.393+0000] {taskinstance.py:1159} INFO - Dependencies all met for dep_context=non-requeueable deps ti=<TaskInstance: dag_finalpro_fredicia.get_data_from_api manual__2023-11-24T14:55:45.268948+00:00 [queued]>
[2023-11-24T14:55:46.402+0000] {taskinstance.py:1159} INFO - Dependencies all met for dep_context=requeueable deps ti=<TaskInstance: dag_finalpro_fredicia.get_data_from_api manual__2023-11-24T14:55:45.268948+00:00 [queued]>
[2023-11-24T14:55:46.403+0000] {taskinstance.py:1361} INFO - Starting attempt 1 of 1
[2023-11-24T14:55:46.416+0000] {taskinstance.py:1382} INFO - Executing <Task(PythonOperator): get_data_from_api> on 2023-11-24 14:55:45.268948+00:00
[2023-11-24T14:55:46.422+0000] {standard_task_runner.py:57} INFO - Started process 322 to run task
[2023-11-24T14:55:46.426+0000] {standard_task_runner.py:84} INFO - Running: ['***', 'tasks', 'run', 'dag_finalpro_fredicia', 'get_data_from_api', 'manual__2023-11-24T14:55:45.268948+00:00', '--job-id', '232', '--raw', '--subdir', 'DAGS_FOLDER/dag-finalpro-fredicia.py', '--cfg-path', '/tmp/tmp2x_jb0y_']
[2023-11-24T14:55:46.428+0000] {standard_task_runner.py:85} INFO - Job 232: Subtask get_data_from_api
[2023-11-24T14:55:46.469+0000] {task_command.py:416} INFO - Running <TaskInstance: dag_finalpro_fredicia.get_data_from_api manual__2023-11-24T14:55:45.268948+00:00 [running]> on host 2a49b9fcd8e7
[2023-11-24T14:55:46.544+0000] {taskinstance.py:1662} INFO - Exporting env vars: AIRFLOW_CTX_DAG_OWNER='***' AIRFLOW_CTX_DAG_ID='dag_finalpro_fredicia' AIRFLOW_CTX_TASK_ID='get_data_from_api' AIRFLOW_CTX_EXECUTION_DATE='2023-11-24T14:55:45.268948+00:00' AIRFLOW_CTX_TRY_NUMBER='1' AIRFLOW_CTX_DAG_RUN_ID='manual__2023-11-24T14:55:45.268948+00:00'
[2023-11-24T14:55:46.553+0000] {taskinstance.py:1937} ERROR - Task failed with exception
Traceback (most recent call last):
  File "/home/airflow/.local/lib/python3.8/site-packages/airflow/operators/python.py", line 192, in execute
    return_value = self.execute_callable()
  File "/home/airflow/.local/lib/python3.8/site-packages/airflow/operators/python.py", line 209, in execute_callable
    return self.python_callable(*self.op_args, **self.op_kwargs)
  File "/opt/airflow/dags/dag-finalpro-fredicia.py", line 13, in func_get_data_from_api
    scraper = CovidScraper(Variable.get('url_covid_traker'))
  File "/home/airflow/.local/lib/python3.8/site-packages/airflow/models/variable.py", line 140, in get
    raise KeyError(f"Variable {key} does not exist")
KeyError: 'Variable url_covid_traker does not exist'
[2023-11-24T14:55:46.562+0000] {taskinstance.py:1400} INFO - Marking task as FAILED. dag_id=dag_finalpro_fredicia, task_id=get_data_from_api, execution_date=20231124T145545, start_date=20231124T145546, end_date=20231124T145546
[2023-11-24T14:55:46.575+0000] {standard_task_runner.py:104} ERROR - Failed to execute job 232 for task get_data_from_api ('Variable url_covid_traker does not exist'; 322)
[2023-11-24T14:55:46.601+0000] {local_task_job_runner.py:228} INFO - Task exited with return code 1
[2023-11-24T14:55:46.625+0000] {taskinstance.py:2778} INFO - 0 downstream tasks scheduled from follow-on schedule check
