[2023-11-26T14:27:41.805+0000] {taskinstance.py:1159} INFO - Dependencies all met for dep_context=non-requeueable deps ti=<TaskInstance: dag_finalpro_fredicia.get_data_from_api manual__2023-11-26T14:13:51.003709+00:00 [queued]>
[2023-11-26T14:27:41.814+0000] {taskinstance.py:1159} INFO - Dependencies all met for dep_context=requeueable deps ti=<TaskInstance: dag_finalpro_fredicia.get_data_from_api manual__2023-11-26T14:13:51.003709+00:00 [queued]>
[2023-11-26T14:27:41.814+0000] {taskinstance.py:1361} INFO - Starting attempt 2 of 1
[2023-11-26T14:27:41.828+0000] {taskinstance.py:1382} INFO - Executing <Task(PythonOperator): get_data_from_api> on 2023-11-26 14:13:51.003709+00:00
[2023-11-26T14:27:41.833+0000] {standard_task_runner.py:57} INFO - Started process 223 to run task
[2023-11-26T14:27:41.834+0000] {standard_task_runner.py:84} INFO - Running: ['***', 'tasks', 'run', 'dag_finalpro_fredicia', 'get_data_from_api', 'manual__2023-11-26T14:13:51.003709+00:00', '--job-id', '285', '--raw', '--subdir', 'DAGS_FOLDER/dag-finalpro-fredicia.py', '--cfg-path', '/tmp/tmphcmt8tww']
[2023-11-26T14:27:41.836+0000] {standard_task_runner.py:85} INFO - Job 285: Subtask get_data_from_api
[2023-11-26T14:27:41.872+0000] {task_command.py:416} INFO - Running <TaskInstance: dag_finalpro_fredicia.get_data_from_api manual__2023-11-26T14:13:51.003709+00:00 [running]> on host 32497ce32ec1
[2023-11-26T14:27:41.932+0000] {taskinstance.py:1662} INFO - Exporting env vars: AIRFLOW_CTX_DAG_OWNER='***' AIRFLOW_CTX_DAG_ID='dag_finalpro_fredicia' AIRFLOW_CTX_TASK_ID='get_data_from_api' AIRFLOW_CTX_EXECUTION_DATE='2023-11-26T14:13:51.003709+00:00' AIRFLOW_CTX_TRY_NUMBER='2' AIRFLOW_CTX_DAG_RUN_ID='manual__2023-11-26T14:13:51.003709+00:00'
[2023-11-26T14:28:09.933+0000] {local_task_job_runner.py:115} ERROR - Received SIGTERM. Terminating subprocesses
[2023-11-26T14:28:09.936+0000] {process_utils.py:131} INFO - Sending 15 to group 223. PIDs of all processes in the group: [223]
[2023-11-26T14:28:09.936+0000] {process_utils.py:86} INFO - Sending the signal 15 to group 223
[2023-11-26T14:28:09.937+0000] {taskinstance.py:1632} ERROR - Received SIGTERM. Terminating subprocesses.
[2023-11-26T14:28:09.949+0000] {taskinstance.py:1937} ERROR - Task failed with exception
Traceback (most recent call last):
  File "/home/airflow/.local/lib/python3.8/site-packages/airflow/operators/python.py", line 192, in execute
    return_value = self.execute_callable()
  File "/home/airflow/.local/lib/python3.8/site-packages/airflow/operators/python.py", line 209, in execute_callable
    return self.python_callable(*self.op_args, **self.op_kwargs)
  File "/opt/airflow/dags/dag-finalpro-fredicia.py", line 14, in func_get_data_from_api
    data = scraper.get_data()
  File "/opt/airflow/dags/modules/covid_scraper.py", line 10, in get_data
    response = requests.get(self.url)
  File "/home/airflow/.local/lib/python3.8/site-packages/requests/api.py", line 73, in get
    return request("get", url, params=params, **kwargs)
  File "/home/airflow/.local/lib/python3.8/site-packages/requests/api.py", line 59, in request
    return session.request(method=method, url=url, **kwargs)
  File "/home/airflow/.local/lib/python3.8/site-packages/requests/sessions.py", line 589, in request
    resp = self.send(prep, **send_kwargs)
  File "/home/airflow/.local/lib/python3.8/site-packages/requests/sessions.py", line 703, in send
    r = adapter.send(request, **kwargs)
  File "/home/airflow/.local/lib/python3.8/site-packages/requests/adapters.py", line 486, in send
    resp = conn.urlopen(
  File "/home/airflow/.local/lib/python3.8/site-packages/urllib3/connectionpool.py", line 714, in urlopen
    httplib_response = self._make_request(
  File "/home/airflow/.local/lib/python3.8/site-packages/urllib3/connectionpool.py", line 415, in _make_request
    conn.request(method, url, **httplib_request_kw)
  File "/home/airflow/.local/lib/python3.8/site-packages/urllib3/connection.py", line 244, in request
    super(HTTPConnection, self).request(method, url, body=body, headers=headers)
  File "/usr/local/lib/python3.8/http/client.py", line 1256, in request
    self._send_request(method, url, body, headers, encode_chunked)
  File "/usr/local/lib/python3.8/http/client.py", line 1302, in _send_request
    self.endheaders(body, encode_chunked=encode_chunked)
  File "/usr/local/lib/python3.8/http/client.py", line 1251, in endheaders
    self._send_output(message_body, encode_chunked=encode_chunked)
  File "/usr/local/lib/python3.8/http/client.py", line 1011, in _send_output
    self.send(msg)
  File "/usr/local/lib/python3.8/http/client.py", line 951, in send
    self.connect()
  File "/home/airflow/.local/lib/python3.8/site-packages/urllib3/connection.py", line 205, in connect
    conn = self._new_conn()
  File "/home/airflow/.local/lib/python3.8/site-packages/urllib3/connection.py", line 174, in _new_conn
    conn = connection.create_connection(
  File "/home/airflow/.local/lib/python3.8/site-packages/urllib3/util/connection.py", line 85, in create_connection
    sock.connect(sa)
  File "/home/airflow/.local/lib/python3.8/site-packages/airflow/models/taskinstance.py", line 1634, in signal_handler
    raise AirflowException("Task received SIGTERM signal")
airflow.exceptions.AirflowException: Task received SIGTERM signal
[2023-11-26T14:28:09.956+0000] {taskinstance.py:1400} INFO - Marking task as FAILED. dag_id=dag_finalpro_fredicia, task_id=get_data_from_api, execution_date=20231126T141351, start_date=20231126T142741, end_date=20231126T142809
[2023-11-26T14:28:09.993+0000] {standard_task_runner.py:104} ERROR - Failed to execute job 285 for task get_data_from_api (Task received SIGTERM signal; 223)
[2023-11-26T14:28:10.029+0000] {process_utils.py:79} INFO - Process psutil.Process(pid=223, status='terminated', exitcode=1, started='14:27:41') (223) terminated with exit code 1
[2023-11-26T14:28:10.030+0000] {local_task_job_runner.py:228} INFO - Task exited with return code 143
[2023-11-26T14:28:10.063+0000] {taskinstance.py:2778} INFO - 0 downstream tasks scheduled from follow-on schedule check
